Workbook
Name cpi: 'Tables and Calculations'!$C$49
Name cpi: 'Tables and Calculations'!$C$49
Name cpi: 'Tables and Calculations'!$C$49
Name cpi: 'Tables and Calculations'!$C$49
Name GST_payable_to_ATO: 'Cash Flow Year 1'!$A$84:$N$84
Name GST_payable_to_ATO: 'Cash Flow Year 2'!$A$84:$N$84
Name GST_payable_to_ATO: 'Cash Flow Year 3'!$A$84:$N$84
Name GST_payable_to_ATO: 'Cash Flow Year 1'!$A$84:$N$84
Name Holidays: #REF!
Name Holidays: #REF!
Name Holidays: #REF!
Name Holidays: #REF!
Name Holidays: #REF!
Name Holidays: #REF!
Name Holidays: #REF!
Name Holidays: #REF!
Name Holidays: #REF!
Name Holidays: #REF!
Name Holidays: #REF!
Name Holidays: #REF!
Name Holidays: #REF!
Name Holidays: #REF!
Name Holidays: #REF!
Name Holidays: #REF!
Name Holidays: #REF!
Name Holidays: #REF!
Name Holidays: #REF!
Name Holidays: #REF!
Name Holidays: #REF!
Name Holidays: #REF!
Name Holidays: #REF!
Name Holidays: 'Quarterly Results'!#REF!
Name Link_CashFlowYr1_R22_SalesRelatedExpenses: 'Cash Flow Year 1'!$A$22:$N$24
Name Link_CashFlowYr1_R22_SalesRelatedExpenses: 'Cash Flow Year 2'!$A$22:$N$24
Name Link_CashFlowYr1_R22_SalesRelatedExpenses: 'Cash Flow Year 3'!$A$22:$N$24
Name Link_CashFlowYr1_R22_SalesRelatedExpenses: 'Cash Flow Year 1'!$A$22:$N$24
Name Link_CashFlowYr1_R27_OverheadExpenses: 'Cash Flow Year 1'!$A$27:$N$73
Name Link_CashFlowYr1_R27_OverheadExpenses: 'Cash Flow Year 2'!$A$27:$N$73
Name Link_CashFlowYr1_R27_OverheadExpenses: 'Cash Flow Year 3'!$A$27:$N$73
Name Link_CashFlowYr1_R27_OverheadExpenses: 'Cash Flow Year 1'!$A$27:$N$73
Name Link_CashFlowYr1_R60_LoanRepayments: 'Cash Flow Year 1'!$A$76:$N$76
Name Link_CashFlowYr1_R60_LoanRepayments: 'Cash Flow Year 2'!$A$76:$N$76
Name Link_CashFlowYr1_R60_LoanRepayments: 'Cash Flow Year 3'!$A$76:$N$76
Name Link_CashFlowYr1_R60_LoanRepayments: 'Cash Flow Year 1'!$A$76:$N$76
Name Link_CashFlowYr1_R61_AssetPurchases: 'Cash Flow Year 1'!$A$79:$O$79
Name Link_CashFlowYr1_R61_AssetPurchases: 'Cash Flow Year 2'!$A$79:$O$79
Name Link_CashFlowYr1_R61_AssetPurchases: 'Cash Flow Year 3'!$A$79:$O$79
Name Link_CashFlowYr1_R61_AssetPurchases: 'Cash Flow Year 1'!$A$79:$O$79
Name Link_CashFlowYr1_R64_Drawings: 'Cash Flow Year 1'!$A$82:$N$82
Name Link_CashFlowYr1_R64_Drawings: 'Cash Flow Year 2'!$A$82:$N$82
Name Link_CashFlowYr1_R64_Drawings: 'Cash Flow Year 3'!$A$82:$N$82
Name Link_CashFlowYr1_R64_Drawings: 'Cash Flow Year 1'!$A$82:$N$82
Name Link_CashFlowYr1_R66_GST: 'Cash Flow Year 1'!$A$84:$N$84
Name Link_CashFlowYr1_R66_GST: 'Cash Flow Year 2'!$A$84:$N$84
Name Link_CashFlowYr1_R66_GST: 'Cash Flow Year 3'!$A$84:$N$84
Name Link_CashFlowYr1_R66_GST: 'Cash Flow Year 1'!$A$84:$N$84
Name Link_CashFlowYr1_R67_PAYGwithholding: 'Cash Flow Year 1'!$A$85:$O$85
Name Link_CashFlowYr1_R67_PAYGwithholding: 'Cash Flow Year 2'!$A$85:$O$85
Name Link_CashFlowYr1_R67_PAYGwithholding: 'Cash Flow Year 3'!$A$85:$O$85
Name Link_CashFlowYr1_R67_PAYGwithholding: 'Cash Flow Year 1'!$A$85:$O$85

Sheet How this Spreadsheet Works
B2: Debra Wylde's Business Advisory
B14: This spreadsheet must be completed using Microsoft Excel
B17: Ensure that you save your work and use version controls to track changes and to avoid confusion. EG: v1 Tom Brown Financial Plan or 09Mar2026 Tom Brown Financial Plan **Including the version number or date in front of the file name will ensure it is ordered sequentially from newest to oldest when searching for files
B26: Save this spreadsheet an Excel Workbook (.xlsx) only DO NOT save it as a 'Excel Macro-Enabled Workbook' or 'Excel Binary Workbook'

Sheet Instructions
A1: Debra Wylde's Business Advisory
A10: This financial planning tool has been thoughtfully developed to support individuals in building clear, structured, and forward-looking business plans. It is designed as a practical framework to guide financial thinking, scenario planning, and decision-making. While care has been taken to reflect relevant Australian regulatory considerations as at July 2022, this tool is intended as a general guide only and should not be relied upon as formal financial or legal advice. We also acknowledge the foundational contribution of Reg Eustace in the original development of this framework.
A11: IMPORTANT INFORMATION
A12: This financial model enables the development of a three-year business forecast, covering both cash flow and profitability projections. For optimal performance, it should be used in Microsoft Excel. Opening the file in other applications may affect formulas, structure, and formatting. Certain worksheets are protected to preserve the integrity of the model. If adjustments are required, they should be made with care to ensure the underlying calculations remain intact.
A13: INSTRUCTIONS TO ASSIST IN COMPLETING THE SPREADSHEET FOR YOUR BUSINESS
A14: Note when filling in the spreadsheet, you are only able to enter data into yellow cells. Other sheets are linked and update according to your inputs. For example, when you enter your business name on the Set Up Details sheet, it flows onto all the other sheets. Only WHOLE NUMBERS will be calculated and FIGURES will be ROUND (ie if you enter $19.95 it will show as $20). REMEMBER THESE ARE ESTIMATES.
A16: Step 1 | B16: Go to the Set Up Details tab and enter known details.
A18: Step 2 | B18: Personal Cash Flow is used for all your personal expenses. Where expenses are both personal and business such as your phone, you need to determine the amount of the expense and insert the total amount in cells O44-O57 appropriately. Then next to the total amount in column P, enter the frequency of payment from the drop-down list. Finally in column Q enter the % of personal use. For example, if your mobile phone plan is $60 per month, and you believe that it will have 30% personal and 70% business use, enter 60 into cell O47, select 'monthly' at P47 and 30% in cell Q47. This process automatically updates the business Cash Flow Year 1 and Year 2 sheet for the business proportions on lines 54-67. Noting in Cash flow Year 2, there will be a CPI adjustment to anticipate the rising cost of expenses.
A20: Step 3 | B20: Go to the Sales Details tab. Initially focus on your main product or service names and enter details in cell A6-A20, accordingly. You will then need to populate the relevant information including the price, trading terms, and payment method. If it is a service there is no need to enter anything in the 'Cost of Goods Sold' column as this relates to products only.
A22: Step 4 | B22: If you have a product, you will need to determine the 'Cost of Goods Sold' in column D, this information will be used to calculate your % 'Gross Profit Margin'. In simple terms, it means how much of the selling price are you keeping after the product is ready for sale. (If you sell goods for $10 and buy them for $6, your gross margin is $4 which is 40% of the selling price).
A24: Step 5 | B24: Then go to the Sales Forecast Year 1 and enter the estimated number of units sold per month for each product or service line. Your estimated volume of sales each month should be entered from cell D7 (depending on sales patterns) until the end of the year for the relevant product or service. The dollar value is automatically calculated from the Sales Details tab.
A26: Step 6 | B26: Repeat Step 4 for your Sales Forecast Year 2 based on your research.
A28: Step 7 | B28: As a consequence of entering the gross margin %, the cost of buying the goods is automatically calculated from the sales forecast volume and included on the Sales Forecast Year 1 & Year 2 in the table - Cost of Sales Schedule. This helps to ensure that your purchases of stock are automatically matching your level of sales, assuming that purchases and sales are in the same month, to maximize cashflow.
A30: Step 8 | B30: Cash Flow Year 1 & 2 - Sole traders enter drawings in line 82, and companies enter director wages/salaries in line 69.
A32: Step 9 | B32: Remember to review data entered regularly. All sheets require research before entering data and may need to be altered as your understanding of the market and business opportunities changes.
A34: Step 10 | B34: Use the key assumptions tabs to explain key considerations, assumptions, and anomalies.

Sheet Set Up Details
A2: 1 | B2: Business Name | C2: Test1 | L2: ='Tables and Calculations'!L4 -> Jan | M2: ='Tables and Calculations'!L4 -> Jan | N2: ='Tables and Calculations'!I4 -> Sole trader | O2: ='Tables and Calculations'!I13 -> Monthly
L3: ='Tables and Calculations'!L5 -> Feb | M3: ='Tables and Calculations'!L5 -> Feb | N3: ='Tables and Calculations'!I5 -> Partnership of 2 | O3: ='Tables and Calculations'!I14 -> Quarterly
A4: 2 | B4: Select the first month of your plan | D4: Jan | L4: ='Tables and Calculations'!L6 -> Mar | M4: ='Tables and Calculations'!L6 -> Mar | N4: ='Tables and Calculations'!I6 -> Partnership of 3
L5: ='Tables and Calculations'!L8 -> May | M5: ='Tables and Calculations'!L7 -> Apr | N5: ='Tables and Calculations'!I7 -> Company
A6: 3 | B6: What trading structure will you operate under? | D6: Sole trader | L6: ='Tables and Calculations'!L9 -> Jun | M6: ='Tables and Calculations'!L8 -> May
L7: ='Tables and Calculations'!L10 -> Jul | M7: ='Tables and Calculations'!L9 -> Jun | N7: Register year 1
A8: 4 | B8: Goods & Services Tax Details | L8: ='Tables and Calculations'!L11 -> Aug | M8: ='Tables and Calculations'!L10 -> Jul | N8: Register year 2
A9: 4.1 | B9: Select your GST registration option | D9: Register year 1 | L9: ='Tables and Calculations'!L12 -> Sep | M9: ='Tables and Calculations'!L11 -> Aug | N9: Not registering for GST
A10: 4.2 | B10: Will you charge GST on sales? | D10: Yes | L10: ='Tables and Calculations'!L13 -> Oct | M10: ='Tables and Calculations'!L12 -> Sep
A11: 4.3 | B11: When will you lodge your BAS? | D11: Monthly | L11: ='Tables and Calculations'!L14 -> Nov | M11: ='Tables and Calculations'!L13 -> Oct | N11: Yes
L12: ='Tables and Calculations'!L15 -> Dec | M12: ='Tables and Calculations'!L14 -> Nov | N12: No
M13: Dec

Sheet Quarterly Results
A1: CASH FLOW YEAR 1 SUMMARY
A2: Enter actual start month here | D2: 45566 | E2: =DATE(YEAR(D2),MONTH(D2)+1,1) -> 45597 | F2: =DATE(YEAR(E2),MONTH(E2)+1,1) -> 45627 | G2: =DATE(YEAR(F2),MONTH(F2)+1,1) -> 45658 | H2: =DATE(YEAR(G2),MONTH(G2)+1,1) -> 45689 | I2: =DATE(YEAR(H2),MONTH(H2)+1,1) -> 45717 | J2: =DATE(YEAR(I2),MONTH(I2)+1,1) -> 45748 | K2: =DATE(YEAR(J2),MONTH(J2)+1,1) -> 45778 | L2: =DATE(YEAR(K2),MONTH(K2)+1,1) -> 45809 | ... O2: =DATE(YEAR(N2),MONTH(N2)+1,1) -> 45901 | P2: TOTAL
C3: Opening Balance | D3: ='Cash Flow Year 1'!C4 -> 0 | E3: ='Cash Flow Year 1'!D4 -> #VALUE! | F3: ='Cash Flow Year 1'!E4 -> #VALUE! | G3: ='Cash Flow Year 1'!F4 -> #VALUE! | H3: ='Cash Flow Year 1'!G4 -> #VALUE! | I3: ='Cash Flow Year 1'!H4 -> #VALUE! | J3: ='Cash Flow Year 1'!I4 -> #VALUE! | K3: ='Cash Flow Year 1'!J4 -> #VALUE! | ... O3: ='Cash Flow Year 1'!N4 -> #VALUE! | P3: =D3 -> 0
A4: Income | C4: (A) | D4: ='Cash Flow Year 1'!C5 -> #VALUE! | E4: ='Cash Flow Year 1'!D5 -> #VALUE! | F4: ='Cash Flow Year 1'!E5 -> #VALUE! | G4: ='Cash Flow Year 1'!F5 -> #VALUE! | H4: ='Cash Flow Year 1'!G5 -> #VALUE! | I4: ='Cash Flow Year 1'!H5 -> #VALUE! | J4: ='Cash Flow Year 1'!I5 -> #VALUE! | K4: ='Cash Flow Year 1'!J5 -> #VALUE! | ... O4: ='Cash Flow Year 1'!N5 -> #VALUE! | P4: =SUM(D4:O4) -> #VALUE!
A5: Expenses | C5: (B) | D5: ='Cash Flow Year 1'!C6 -> #VALUE! | E5: ='Cash Flow Year 1'!D6 -> #VALUE! | F5: ='Cash Flow Year 1'!E6 -> #VALUE! | G5: ='Cash Flow Year 1'!F6 -> #VALUE! | H5: ='Cash Flow Year 1'!G6 -> #VALUE! | I5: ='Cash Flow Year 1'!H6 -> #VALUE! | J5: ='Cash Flow Year 1'!I6 -> #VALUE! | K5: ='Cash Flow Year 1'!J6 -> #VALUE! | ... O5: ='Cash Flow Year 1'!N6 -> #VALUE! | P5: =SUM(D5:O5) -> #VALUE!
A6: Balance (A minus B) | C6: (C) | D6: =SUM(D4-D5) -> #VALUE! | E6: =SUM(E4-E5) -> #VALUE! | F6: =SUM(F4-F5) -> #VALUE! | G6: =SUM(G4-G5) -> #VALUE! | H6: =SUM(H4-H5) -> #VALUE! | I6: =SUM(I4-I5) -> #VALUE! | J6: =SUM(J4-J5) -> #VALUE! | K6: =SUM(K4-K5) -> #VALUE! | ... O6: =SUM(O4-O5) -> #VALUE! | P6: =SUM(D6:O6) -> #VALUE!
A7: QUARTER | D7: 1 | E7: =D7+E9 -> 1 | F7: =E7+F9 -> 1 | G7: =F7+G9 -> 2 | H7: =G7+H9 -> 2 | I7: =H7+I9 -> 2 | J7: =I7+J9 -> 3 | K7: =J7+K9 -> 3 | L7: =K7+L9 -> 3 | ... O7: =N7+O9 -> 4
A8: Last month of Qtr | D8: =IF(D7,E9,"") -> FALSE | E8: =IF(E7,F9,"") -> FALSE | F8: =IF(F7,G9,"") -> TRUE | G8: =IF(G7,H9,"") -> FALSE | H8: =IF(H7,I9,"") -> FALSE | I8: =IF(I7,J9,"") -> TRUE | J8: =IF(J7,K9,"") -> FALSE | K8: =IF(K7,L9,"") -> FALSE | ... O8: =IF(O7,P9,"") -> 0
A9: Start of new Qtr | D9: =INT(MONTH(D2-1)/3)=MONTH(D2-1)/3 -> TRUE | E9: =INT(MONTH(E2-1)/3)=MONTH(E2-1)/3 -> FALSE | F9: =INT(MONTH(F2-1)/3)=MONTH(F2-1)/3 -> FALSE | G9: =INT(MONTH(G2-1)/3)=MONTH(G2-1)/3 -> TRUE | H9: =INT(MONTH(H2-1)/3)=MONTH(H2-1)/3 -> FALSE | I9: =INT(MONTH(I2-1)/3)=MONTH(I2-1)/3 -> FALSE | J9: =INT(MONTH(J2-1)/3)=MONTH(J2-1)/3 -> TRUE | K9: =INT(MONTH(K2-1)/3)=MONTH(K2-1)/3 -> FALSE | ... O9: =INT(MONTH(O2-1)/3)=MONTH(O2-1)/3 -> FALSE
D10: The exact result will depend on the number of days/weeks before the end of the quarter
D13: Income Statement Planned Forecast
C15: Quarter | F15: 1 | H15: 2 | J15: 3 | L15: 4 | N15: 5
C16: (A) INCOME | F16: =SUMIF($D$7:$O$7,$F15,$D$4:$O$4) -> #VALUE! | H16: =SUMIF($D$7:$O$7,$H15,$D$4:$O$4) -> #VALUE! | J16: =SUMIF($D$7:$O$7,$J15,$D$4:$O$4) -> #VALUE! | L16: =SUMIF($D$7:$O$7,$L15,$D$4:$O$4) -> #VALUE! | N16: =SUMIF($D$7:$O$7,$N15,$D$4:$O$4) -> 0
C17: (B) EXPENSES | F17: =SUMIF($D$7:$O$7,$F15,$D$5:$O$5) -> #VALUE! | H17: =SUMIF($D$7:$O$7,$H15,$D$5:$O$5) -> #VALUE! | J17: =SUMIF($D$7:$O$7,$J15,$D$5:$O$5) -> #VALUE! | L17: =SUMIF($D$7:$O$7,$L15,$D$5:$O$5) -> #VALUE! | N17: =SUMIF($D$7:$O$7,$N15,$D$5:$O$5) -> 0
C18: (C) BALANCE (A minus B) | F18: =SUMIF($D$7:$O$7,$F15,$D$6:$O$6) -> #VALUE! | H18: =SUMIF($D$7:$O$7,$H15,$D$6:$O$6) -> #VALUE! | J18: =SUMIF($D$7:$O$7,$J15,$D$6:$O$6) -> #VALUE! | L18: =SUMIF($D$7:$O$7,$L15,$D$6:$O$6) -> #VALUE! | N18: =SUMIF($D$7:$O$7,$N15,$D$6:$O$6) -> 0

Sheet Personal Cash Flow Budget Y1
A1: Financial Plan of | B1: ='Set Up Details'!C2 -> Test1
A2: PERSONAL CASH FLOW FOR YEAR 1
B3: Enter opening balance of personal bank account
B4: ='Tables and Calculations'!B2 -> Jan | C4: ='Tables and Calculations'!C2 -> Feb | D4: ='Tables and Calculations'!D2 -> Mar | E4: ='Tables and Calculations'!E2 -> Apr | F4: ='Tables and Calculations'!F2 -> May | G4: ='Tables and Calculations'!G2 -> Jun | H4: ='Tables and Calculations'!H2 -> Jul | I4: ='Tables and Calculations'!I2 -> Aug | ... M4: ='Tables and Calculations'!M2 -> Dec | N4: Total
A5: Bank Balance | C5: =B58 -> 0 | D5: =C58 -> 0 | E5: =D58 -> 0 | F5: =E58 -> 0 | G5: =F58 -> 0 | H5: =G58 -> 0 | I5: =H58 -> 0 | J5: =I58 -> 0 | ... M5: =L58 -> 0 | N5: =B5 -> 0
A6: Personal Cash Inflows
A7: =IF('Cash Flow Year 1'!O70>1, "Directors Salary","Drawings from business") -> Drawings from business | B7: =IF('Set Up Details'!$D$6="Company",'Cash Flow Year 1'!C70,'Cash Flow Year 1'!C82) -> 0 | C7: =IF('Set Up Details'!$D$6="Company",'Cash Flow Year 1'!D70,'Cash Flow Year 1'!D82) -> 0 | D7: =IF('Set Up Details'!$D$6="Company",'Cash Flow Year 1'!E70,'Cash Flow Year 1'!E82) -> 0 | E7: =IF('Set Up Details'!$D$6="Company",'Cash Flow Year 1'!F70,'Cash Flow Year 1'!F82) -> 0 | F7: =IF('Set Up Details'!$D$6="Company",'Cash Flow Year 1'!G70,'Cash Flow Year 1'!G82) -> 0 | G7: =IF('Set Up Details'!$D$6="Company",'Cash Flow Year 1'!H70,'Cash Flow Year 1'!H82) -> 0 | H7: =IF('Set Up Details'!$D$6="Company",'Cash Flow Year 1'!I70,'Cash Flow Year 1'!I82) -> 0 | I7: =IF('Set Up Details'!$D$6="Company",'Cash Flow Year 1'!J70,'Cash Flow Year 1'!J82) -> 0 | ... M7: =IF('Set Up Details'!$D$6="Company",'Cash Flow Year 1'!N70,'Cash Flow Year 1'!N82) -> 0 | N7: =SUM(B7:M7) -> 0
A8: Other Personal Income
A9: Part-time/casual work | N9: =SUM(B9:M9) -> 0
A10: Spouse/partner wages | N10: =SUM(B10:M10) -> 0
A11: Govt Payments (e.g. Family Tax Benefit, Carers Payment) | N11: =SUM(B11:M11) -> 0
A12: Other income (hobby, investments) | N12: =SUM(B12:M12) -> 0
N13: =SUM(B13:M13) -> 0
A14: Total Cash Receipts | B14: =SUM(B7:B13) -> 0 | C14: =SUM(C7:C13) -> 0 | D14: =SUM(D7:D13) -> 0 | E14: =SUM(E7:E13) -> 0 | F14: =SUM(F7:F13) -> 0 | G14: =SUM(G7:G13) -> 0 | H14: =SUM(H7:H13) -> 0 | I14: =SUM(I7:I13) -> 0 | ... N14: =SUM(N7:N13) -> 0
A15: Personal Cash Outflows
A16: Groceries | N16: =SUM(B16:M16) -> 0
A17: Entertainment/Recreation | N17: =SUM(B17:M17) -> 0
A18: Clothing/Footwear | N18: =SUM(B18:M18) -> 0
A19: Home Insurance | N19: =SUM(B19:M19) -> 0
A20: Health/Other Insurance | N20: =SUM(B20:M20) -> 0
A21: Council Rates | N21: =SUM(B21:M21) -> 0
A22: Medical Expenses | N22: =SUM(B22:M22) -> 0
A23: Fuel for personal use | N23: =SUM(B23:M23) -> 0
A24: Transport - fares, taxi/uber | N24: =SUM(B24:M24) -> 0
A25: Childcare | N25: =SUM(B25:M25) -> 0
A26: School fees & education costs | N26: =SUM(B26:M26) -> 0
A27: Pets | N27: =SUM(B27:M27) -> 0
... A36: Vehicle Loan | N36: =SUM(B36:M36) -> 0
N37: =SUM(B37:M37) -> 0
N38: =SUM(B38:M38) -> 0 | O38: Enter the amount in correct column based on freqncy of the payment frequency
A39: Personal loan repayments | N39: =SUM(B39:M39) -> 0
A40: Personal credit card repayments | N40: =SUM(B40:M40) -> 0 | R40: Personal Cash Flow | V40: Business Cash Flow
A41: Shared costs (personal and business) | O41: Total Amount | P41: Frequency of payment | Q41: % of cost considered personal | R41: Monthly | S41: Quarterly | T41: Bi-annually | U41: Annually | V41: % of cost considered businessl | W41: Monthly | X41: Quarterly | Y41: Annually
A42: Household Rent | B42: =IF(P42="Monthly",R42,IF(P42="Quarterly",S42,IF(P42="Bi-Annually",T42,IF(P42="Annually",U42)))) -> 0 | C42: =IF(P42="Monthly",R42,IF(P42="Quarterly",0,IF(P42="Bi-Annually",0,IF(P42="Annually",0)))) -> 0 | D42: =IF(P42="Monthly",R42,IF(P42="Quarterly",0,IF(P42="Bi-Annually",0,IF(P42="Annually",0)))) -> 0 | E42: =IF(P42="Monthly",R42,IF(P42="Quarterly",S42,IF(P42="Bi-Annually",0,IF(P42="Annually",0)))) -> 0 | F42: =IF(P42="Monthly",R42,IF(P42="Quarterly",0,IF(P42="Bi-Annually",0,IF(P42="Annually",0)))) -> 0 | G42: =IF(P42="Monthly",R42,IF(P42="Quarterly",0,IF(P42="Bi-Annually",0,IF(P42="Annually",0)))) -> 0 | H42: =IF(P42="Monthly",R42,IF(P42="Quarterly",S42,IF(P42="Bi-Annually",T42,IF(P42="Annually",0)))) -> 0 | I42: =IF(P42="Monthly",R42,IF(P42="Quarterly",0,IF(P42="Bi-Annually",0,IF(P42="Annually",0)))) -> 0 | J42: =IF(P42="Monthly",R42,IF(P42="Quarterly",0,IF(P42="Bi-Annually",0,IF(P42="Annually",0)))) -> 0 | K42: =IF(P42="Monthly",R42,IF(P42="Quarterly",S42,IF(P42="Bi-Annually",0,IF(P42="Annually",0)))) -> 0 | L42: =IF(P42="Monthly",R42,IF(P42="Quarterly",0,IF(P42="Bi-Annually",0,IF(P42="Annually",0)))) -> 0 | M42: =IF(P42="Monthly",R42,IF(P42="Quarterly",0,IF(P42="Bi-Annually",0,IF(P42="Annually",0)))) -> 0 | N42: =SUM(B42:M42) -> 0 | P42: Monthly | Q42: 1 | R42: =IF(Q42<=0,0,O42*Q42) -> 0 | S42: =IF(Q42<=0,0,O42*Q42) -> 0 | T42: =IF(Q42<=0,0,O42*Q42) -> 0 | U42: =IF(S42<=0,0,O42*Q42) -> 0 | V42: =SUM(100%-Q42) -> 0 | W42: =IF(V42<=0,0,O42*V42) -> 0 | X42: =IF(W42<=0,0,O42*V42) -> 0 | Y42: =IF(X42<=0,0,O42*V42) -> 0
A43: Telephone | B43: =IF(P43="Monthly",R43,IF(P43="Quarterly",S43,IF(P43="Bi-Annually",T43,IF(P43="Annually",U43)))) -> 0 | C43: =IF(P43="Monthly",R43,IF(P43="Quarterly",0,IF(P43="Bi-Annually",0,IF(P43="Annually",0)))) -> 0 | D43: =IF(P43="Monthly",R43,IF(P43="Quarterly",0,IF(P43="Bi-Annually",0,IF(P43="Annually",0)))) -> 0 | E43: =IF(P43="Monthly",R43,IF(P43="Quarterly",S43,IF(P43="Bi-Annually",0,IF(P43="Annually",0)))) -> 0 | F43: =IF(P43="Monthly",R43,IF(P43="Quarterly",0,IF(P43="Bi-Annually",0,IF(P43="Annually",0)))) -> 0 | G43: =IF(P43="Monthly",R43,IF(P43="Quarterly",0,IF(P43="Bi-Annually",0,IF(P43="Annually",0)))) -> 0 | H43: =IF(P43="Monthly",R43,IF(P43="Quarterly",S43,IF(P43="Bi-Annually",T43,IF(P43="Annually",0)))) -> 0 | I43: =IF(P43="Monthly",R43,IF(P43="Quarterly",0,IF(P43="Bi-Annually",0,IF(P43="Annually",0)))) -> 0 | J43: =IF(P43="Monthly",R43,IF(P43="Quarterly",0,IF(P43="Bi-Annually",0,IF(P43="Annually",0)))) -> 0 | K43: =IF(P43="Monthly",R43,IF(P43="Quarterly",S43,IF(P43="Bi-Annually",0,IF(P43="Annually",0)))) -> 0 | L43: =IF(P43="Monthly",R43,IF(P43="Quarterly",0,IF(P43="Bi-Annually",0,IF(P43="Annually",0)))) -> 0 | M43: =IF(P43="Monthly",R43,IF(P43="Quarterly",0,IF(P43="Bi-Annually",0,IF(P43="Annually",0)))) -> 0 | N43: =SUM(B43:M43) -> 0 | P43: Monthly | Q43: 1 | R43: =IF(Q43<=0,0,O43*Q43) -> 0 | S43: =IF(Q43<=0,0,O43*Q43) -> 0 | T43: =IF(Q43<=0,0,O43*Q43) -> 0 | U43: =IF(S43<=0,0,O43*Q43) -> 0 | V43: =SUM(100%-Q43) -> 0 | W43: =IF(V43<=0,0,O43*V43) -> 0 | X43: =IF(W43<=0,0,O43*V43) -> 0 | Y43: =IF(X43<=0,0,O43*V43) -> 0
A44: Internet | B44: =IF(P44="Monthly",R44,IF(P44="Quarterly",S44,IF(P44="Bi-Annually",T44,IF(P44="Annually",U44)))) -> 0 | C44: =IF(P44="Monthly",R44,IF(P44="Quarterly",0,IF(P44="Bi-Annually",0,IF(P44="Annually",0)))) -> 0 | D44: =IF(P44="Monthly",R44,IF(P44="Quarterly",0,IF(P44="Bi-Annually",0,IF(P44="Annually",0)))) -> 0 | E44: =IF(P44="Monthly",R44,IF(P44="Quarterly",S44,IF(P44="Bi-Annually",0,IF(P44="Annually",0)))) -> 0 | F44: =IF(P44="Monthly",R44,IF(P44="Quarterly",0,IF(P44="Bi-Annually",0,IF(P44="Annually",0)))) -> 0 | G44: =IF(P44="Monthly",R44,IF(P44="Quarterly",0,IF(P44="Bi-Annually",0,IF(P44="Annually",0)))) -> 0 | H44: =IF(P44="Monthly",R44,IF(P44="Quarterly",S44,IF(P44="Bi-Annually",T44,IF(P44="Annually",0)))) -> 0 | I44: =IF(P44="Monthly",R44,IF(P44="Quarterly",0,IF(P44="Bi-Annually",0,IF(P44="Annually",0)))) -> 0 | J44: =IF(P44="Monthly",R44,IF(P44="Quarterly",0,IF(P44="Bi-Annually",0,IF(P44="Annually",0)))) -> 0 | K44: =IF(P44="Monthly",R44,IF(P44="Quarterly",S44,IF(P44="Bi-Annually",0,IF(P44="Annually",0)))) -> 0 | L44: =IF(P44="Monthly",R44,IF(P44="Quarterly",0,IF(P44="Bi-Annually",0,IF(P44="Annually",0)))) -> 0 | M44: =IF(P44="Monthly",R44,IF(P44="Quarterly",0,IF(P44="Bi-Annually",0,IF(P44="Annually",0)))) -> 0 | N44: =SUM(B44:M44) -> 0 | P44: Monthly | Q44: 1 | R44: =IF(Q44<=0,0,O44*Q44) -> 0 | S44: =IF(Q44<=0,0,O44*Q44) -> 0 | T44: =IF(Q44<=0,0,O44*Q44) -> 0 | U44: =IF(S44<=0,0,O44*Q44) -> 0 | V44: =SUM(100%-Q44) -> 0 | W44: =IF(V44<=0,0,O44*V44) -> 0 | X44: =IF(W44<=0,0,O44*V44) -> 0 | Y44: =IF(X44<=0,0,O44*V44) -> 0
A45: Mobile | B45: =IF(P45="Monthly",R45,IF(P45="Quarterly",S45,IF(P45="Bi-Annually",T45,IF(P45="Annually",U45)))) -> 0 | C45: =IF(P45="Monthly",R45,IF(P45="Quarterly",0,IF(P45="Bi-Annually",0,IF(P45="Annually",0)))) -> 0 | D45: =IF(P45="Monthly",R45,IF(P45="Quarterly",0,IF(P45="Bi-Annually",0,IF(P45="Annually",0)))) -> 0 | E45: =IF(P45="Monthly",R45,IF(P45="Quarterly",S45,IF(P45="Bi-Annually",0,IF(P45="Annually",0)))) -> 0 | F45: =IF(P45="Monthly",R45,IF(P45="Quarterly",0,IF(P45="Bi-Annually",0,IF(P45="Annually",0)))) -> 0 | G45: =IF(P45="Monthly",R45,IF(P45="Quarterly",0,IF(P45="Bi-Annually",0,IF(P45="Annually",0)))) -> 0 | H45: =IF(P45="Monthly",R45,IF(P45="Quarterly",S45,IF(P45="Bi-Annually",T45,IF(P45="Annually",0)))) -> 0 | I45: =IF(P45="Monthly",R45,IF(P45="Quarterly",0,IF(P45="Bi-Annually",0,IF(P45="Annually",0)))) -> 0 | J45: =IF(P45="Monthly",R45,IF(P45="Quarterly",0,IF(P45="Bi-Annually",0,IF(P45="Annually",0)))) -> 0 | K45: =IF(P45="Monthly",R45,IF(P45="Quarterly",S45,IF(P45="Bi-Annually",0,IF(P45="Annually",0)))) -> 0 | L45: =IF(P45="Monthly",R45,IF(P45="Quarterly",0,IF(P45="Bi-Annually",0,IF(P45="Annually",0)))) -> 0 | M45: =IF(P45="Monthly",R45,IF(P45="Quarterly",0,IF(P45="Bi-Annually",0,IF(P45="Annually",0)))) -> 0 | N45: =SUM(B45:M45) -> 0 | P45: Monthly | Q45: 1 | R45: =IF(Q45<=0,0,O45*Q45) -> 0 | S45: =IF(Q45<=0,0,O45*Q45) -> 0 | T45: =IF(Q45<=0,0,O45*Q45) -> 0 | U45: =IF(S45<=0,0,O45*Q45) -> 0 | V45: =SUM(100%-Q45) -> 0 | W45: =IF(V45<=0,0,O45*V45) -> 0 | X45: =IF(W45<=0,0,O45*V45) -> 0 | Y45: =IF(X45<=0,0,O45*V45) -> 0
A46: Motor vehicle - Repairs and Maintenance | B46: =IF(P46="Monthly",R46,IF(P46="Quarterly",S46,IF(P46="Bi-Annually",T46,IF(P46="Annually",U46)))) -> 0 | C46: =IF(P46="Monthly",R46,IF(P46="Quarterly",0,IF(P46="Bi-Annually",0,IF(P46="Annually",0)))) -> 0 | D46: =IF(P46="Monthly",R46,IF(P46="Quarterly",0,IF(P46="Bi-Annually",0,IF(P46="Annually",0)))) -> 0 | E46: =IF(P46="Monthly",R46,IF(P46="Quarterly",S46,IF(P46="Bi-Annually",0,IF(P46="Annually",0)))) -> 0 | F46: =IF(P46="Monthly",R46,IF(P46="Quarterly",0,IF(P46="Bi-Annually",0,IF(P46="Annually",0)))) -> 0 | G46: =IF(P46="Monthly",R46,IF(P46="Quarterly",0,IF(P46="Bi-Annually",0,IF(P46="Annually",0)))) -> 0 | H46: =IF(P46="Monthly",R46,IF(P46="Quarterly",S46,IF(P46="Bi-Annually",T46,IF(P46="Annually",0)))) -> 0 | I46: =IF(P46="Monthly",R46,IF(P46="Quarterly",0,IF(P46="Bi-Annually",0,IF(P46="Annually",0)))) -> 0 | J46: =IF(P46="Monthly",R46,IF(P46="Quarterly",0,IF(P46="Bi-Annually",0,IF(P46="Annually",0)))) -> 0 | K46: =IF(P46="Monthly",R46,IF(P46="Quarterly",S46,IF(P46="Bi-Annually",0,IF(P46="Annually",0)))) -> 0 | L46: =IF(P46="Monthly",R46,IF(P46="Quarterly",0,IF(P46="Bi-Annually",0,IF(P46="Annually",0)))) -> 0 | M46: =IF(P46="Monthly",R46,IF(P46="Quarterly",0,IF(P46="Bi-Annually",0,IF(P46="Annually",0)))) -> 0 | N46: =SUM(B46:M46) -> 0 | P46: Monthly | Q46: 1 | R46: =IF(Q46<=0,0,O46*Q46) -> 0 | S46: =IF(Q46<=0,0,O46*Q46) -> 0 | T46: =IF(Q46<=0,0,O46*Q46) -> 0 | U46: =IF(S46<=0,0,O46*Q46) -> 0 | V46: =SUM(100%-Q46) -> 0 | W46: =IF(V46<=0,0,O46*V46) -> 0 | X46: =IF(W46<=0,0,O46*V46) -> 0 | Y46: =IF(X46<=0,0,O46*V46) -> 0
A47: Motor vehicle - Registration | B47: =IF(P47="Monthly",R47,IF(P47="Quarterly",S47,IF(P47="Bi-Annually",T47,IF(P47="Annually",U47)))) -> 0 | C47: =IF(P47="Monthly",R47,IF(P47="Quarterly",0,IF(P47="Bi-Annually",0,IF(P47="Annually",0)))) -> 0 | D47: =IF(P47="Monthly",R47,IF(P47="Quarterly",0,IF(P47="Bi-Annually",0,IF(P47="Annually",0)))) -> 0 | E47: =IF(P47="Monthly",R47,IF(P47="Quarterly",S47,IF(P47="Bi-Annually",0,IF(P47="Annually",0)))) -> 0 | F47: =IF(P47="Monthly",R47,IF(P47="Quarterly",0,IF(P47="Bi-Annually",0,IF(P47="Annually",0)))) -> 0 | G47: =IF(P47="Monthly",R47,IF(P47="Quarterly",0,IF(P47="Bi-Annually",0,IF(P47="Annually",0)))) -> 0 | H47: =IF(P47="Monthly",R47,IF(P47="Quarterly",S47,IF(P47="Bi-Annually",T47,IF(P47="Annually",0)))) -> 0 | I47: =IF(P47="Monthly",R47,IF(P47="Quarterly",0,IF(P47="Bi-Annually",0,IF(P47="Annually",0)))) -> 0 | J47: =IF(P47="Monthly",R47,IF(P47="Quarterly",0,IF(P47="Bi-Annually",0,IF(P47="Annually",0)))) -> 0 | K47: =IF(P47="Monthly",R47,IF(P47="Quarterly",S47,IF(P47="Bi-Annually",0,IF(P47="Annually",0)))) -> 0 | L47: =IF(P47="Monthly",R47,IF(P47="Quarterly",0,IF(P47="Bi-Annually",0,IF(P47="Annually",0)))) -> 0 | M47: =IF(P47="Monthly",R47,IF(P47="Quarterly",0,IF(P47="Bi-Annually",0,IF(P47="Annually",0)))) -> 0 | N47: =SUM(B47:M47) -> 0 | P47: Monthly | Q47: 1 | R47: =IF(Q47<=0,0,O47*Q47) -> 0 | S47: =IF(Q47<=0,0,O47*Q47) -> 0 | T47: =IF(Q47<=0,0,O47*Q47) -> 0 | U47: =IF(S47<=0,0,O47*Q47) -> 0 | V47: =SUM(100%-Q47) -> 0 | W47: =IF(V47<=0,0,O47*V47) -> 0 | X47: =IF(W47<=0,0,O47*V47) -> 0 | Y47: =IF(X47<=0,0,O47*V47) -> 0
A48: Motor vehicle - Insurance | B48: =IF(P48="Monthly",R48,IF(P48="Quarterly",S48,IF(P48="Bi-Annually",T48,IF(P48="Annually",U48)))) -> 0 | C48: =IF(P48="Monthly",R48,IF(P48="Quarterly",0,IF(P48="Bi-Annually",0,IF(P48="Annually",0)))) -> 0 | D48: =IF(P48="Monthly",R48,IF(P48="Quarterly",0,IF(P48="Bi-Annually",0,IF(P48="Annually",0)))) -> 0 | E48: =IF(P48="Monthly",R48,IF(P48="Quarterly",S48,IF(P48="Bi-Annually",0,IF(P48="Annually",0)))) -> 0 | F48: =IF(P48="Monthly",R48,IF(P48="Quarterly",0,IF(P48="Bi-Annually",0,IF(P48="Annually",0)))) -> 0 | G48: =IF(P48="Monthly",R48,IF(P48="Quarterly",0,IF(P48="Bi-Annually",0,IF(P48="Annually",0)))) -> 0 | H48: =IF(P48="Monthly",R48,IF(P48="Quarterly",S48,IF(P48="Bi-Annually",T48,IF(P48="Annually",0)))) -> 0 | I48: =IF(P48="Monthly",R48,IF(P48="Quarterly",0,IF(P48="Bi-Annually",0,IF(P48="Annually",0)))) -> 0 | J48: =IF(P48="Monthly",R48,IF(P48="Quarterly",0,IF(P48="Bi-Annually",0,IF(P48="Annually",0)))) -> 0 | K48: =IF(P48="Monthly",R48,IF(P48="Quarterly",S48,IF(P48="Bi-Annually",0,IF(P48="Annually",0)))) -> 0 | L48: =IF(P48="Monthly",R48,IF(P48="Quarterly",0,IF(P48="Bi-Annually",0,IF(P48="Annually",0)))) -> 0 | M48: =IF(P48="Monthly",R48,IF(P48="Quarterly",0,IF(P48="Bi-Annually",0,IF(P48="Annually",0)))) -> 0 | N48: =SUM(B48:M48) -> 0 | P48: Monthly | Q48: 1 | R48: =IF(Q48<=0,0,O48*Q48) -> 0 | S48: =IF(Q48<=0,0,O48*Q48) -> 0 | T48: =IF(Q48<=0,0,O48*Q48) -> 0 | U48: =IF(S48<=0,0,O48*Q48) -> 0 | V48: =SUM(100%-Q48) -> 0 | W48: =IF(V48<=0,0,O48*V48) -> 0 | X48: =IF(W48<=0,0,O48*V48) -> 0 | Y48: =IF(X48<=0,0,O48*V48) -> 0
...

Sheet Assets and Depreciation
A1: Financial Plan of | B1: ='Set Up Details'!C2 -> Test1
A3: Personal Assets brought into the business | M3: Business Liabilities
A4: Current Assets | B4: $ Value | C4: Business Share | E4: Value of Business Asset | G4: Effective Life | H4: Rate % | I4: DEPR Y1 | J4: DEPR Y2 | M4: What business debts will you start with?
A5: Office Furniture | C5: 1 | E5: =SUM(B5*C5) -> 0 | H5: =IF(ISERROR(1/G5),0,1/G5) -> 0 | I5: =(E5*H5) -> 0 | J5: =IF(H5<=100%,(E5*H5),0) -> 0 | M5: GST owing from market testing
A6: Computer Equipment | C6: 1 | E6: =SUM(B6*C6) -> 0 | H6: =IF(ISERROR(1/G6),0,1/G6) -> 0 | I6: =(E6*H6) -> 0 | J6: =IF(H6<=100%,(E6*H6),0) -> 0
A7: Motor Vehicle | C7: 1 | E7: =SUM(B7*C7) -> 0 | H7: =IF(ISERROR(1/G7),0,1/G7) -> 0 | I7: =(E7*H7) -> 0 | J7: =IF(H7<=100%,(E7*H7),0) -> 0 | M7: Existing Business Loans (amount owing) | S7: Monthly Payment $ | V7: =ROUND(SUM(Q7/V9+V8),0) -> 0
A8: Tools | C8: 1 | E8: =SUM(B8*C8) -> 0 | H8: =IF(ISERROR(1/G8),0,1/G8) -> 0 | I8: =(E8*H8) -> 0 | J8: =IF(H8<=100%,(E8*H8),0) -> 0 | S8: Interest per month $
A9: Mobile Phone | C9: 1 | E9: =SUM(B9*C9) -> 0 | H9: =IF(ISERROR(1/G9),0,1/G9) -> 0 | I9: =(E9*H9) -> 0 | J9: =IF(H9<=100%,(E9*H9),0) -> 0 | S9: Months remaining on loan | V9: 1 | X9: =V9 -> 1
C10: 1 | E10: =SUM(B10*C10) -> 0 | H10: =IF(ISERROR(1/G10),0,1/G10) -> 0 | I10: =(E10*H10) -> 0 | J10: =IF(H10<=100%,(E10*H10),0) -> 0 | S10: Interest Paid Y1 | V10: =ROUND(IF(V9>=12,(12*V8),IF(OR(V9<12),(X9*V8),0)),0) -> 0 | X10: =V9-X11 -> 12
C11: 1 | E11: =SUM(B11*C11) -> 0 | H11: =IF(ISERROR(1/G11),0,1/G11) -> 0 | I11: =(E11*H11) -> 0 | J11: =IF(H11<=100%,(E11*H11),0) -> 0 | S11: Interest Paid Y2 | V11: =ROUND(IF(X11<=0,(V8*0),IF(X11>12,(V8*12),IF(X11<12,V8*X11))),0) -> 0 | X11: =SUM(V9-12) -> -11
C12: 1 | E12: =SUM(B12*C12) -> 0 | H12: =IF(ISERROR(1/G12),0,1/G12) -> 0 | I12: =(E12*H12) -> 0 | J12: =IF(H12<=100%,(E12*H12),0) -> 0
E13: =SUM(E5:E12) -> 0 | I13: =SUM(I5:I12) -> 0 | J13: =SUM(J5:J12) -> 0
A15: Business Assets at Commencement
A16: Current Assets | B16: $ Value
A17: Opening Bank Balance
A18: Value of Opening Stock
A19: Debtors
A20: Total | B20: =SUM(B17:E19) -> 0
A22: Assets purchased after commencement | K22: DEPR YR1 | L22: DEPR YR2
A23: Asset | B23: Start Date(dd-mmm-yy) | G23: Number of days | I23: Effective Life | J23: Rate %
B24: Purchase Price (excl. GST) | C24: GST | D24: Total Price | E24: Purchase Date | G24: DEPR YR1 | H24: DEPR YR2
D25: =SUM(B25:C25) -> 0 | F25: =MONTH(E25)-MONTH(E23)+12*(YEAR(E25)-YEAR(E23)) -> 0 | G25: =MIN(365,MAX(0,$E$23+365-$E25)) -> 365 | H25: 365 | J25: =IF(ISERROR(1/I25),0,1/I25) -> 0 | K25: =IF(I25>1,(($B25*$J25)/365*$G25),B25) -> 0 | L25: =IF(K25<B25,B25*J25/365*H25,0) -> 0
C26: =B26*0.1 -> 0 | D26: =SUM(B26:C26) -> 0 | F26: =MONTH(E26)-MONTH(E23)+12*(YEAR(E26)-YEAR(E23)) -> 0 | G26: =MIN(365,MAX(0,$E$23+365-$E26)) -> 365 | H26: 365 | J26: =IF(ISERROR(1/I26),0,1/I26) -> 0 | K26: =IF(I26>1,(($B26*$J26)/365*$G26),B26) -> 0 | L26: =IF(K26<B26,B26*J26/365*H26,0) -> 0
C27: =B27*0.1 -> 0 | D27: =SUM(B27:C27) -> 0 | F27: =MONTH(E27)-MONTH(E23)+12*(YEAR(E27)-YEAR(E23)) -> 0 | G27: =MIN(365,MAX(0,$E$23+365-$E27)) -> 365 | H27: 365 | J27: =IF(ISERROR(1/I27),0,1/I27) -> 0 | K27: =IF(I27>1,(($B27*$J27)/365*$G27),B27) -> 0 | L27: =IF(K27<B27,B27*J27/365*H27,0) -> 0
C28: =B28*0.1 -> 0 | D28: =SUM(B28:C28) -> 0 | F28: =MONTH(E28)-MONTH(E23)+12*(YEAR(E28)-YEAR(E23)) -> 0 | G28: =MIN(365,MAX(0,$E$23+365-$E28)) -> 365 | H28: 365 | J28: =IF(ISERROR(1/I28),0,1/I28) -> 0 | K28: =IF(I28>1,(($B28*$J28)/365*$G28),B28) -> 0 | L28: =IF(K28<B28,B28*J28/365*H28,0) -> 0
C29: =B29*0.1 -> 0 | D29: =SUM(B29:C29) -> 0 | F29: =MONTH(E29)-MONTH(E23)+12*(YEAR(E29)-YEAR(E23)) -> 0 | G29: =MIN(365,MAX(0,$E$23+365-$E29)) -> 365 | H29: 365 | J29: =IF(ISERROR(1/I29),0,1/I29) -> 0 | K29: =IF(I29>1,(($B29*$J29)/365*$G29),B29) -> 0 | L29: =IF(K29<B29,B29*J29/365*H29,0) -> 0
A30: Totals | B30: =SUM(B25:B29) -> 0 | C30: =SUM(C25:C29) -> 0 | D30: =SUM(D25:D29) -> 0 | K30: =SUM(K25:K29) -> 0 | L30: =SUM(L25:L29) -> 0
A32: TOTAL BUSINESS ASSETS AT COMMENCEMENT | B32: =SUM(E13+B20) -> 0 | G32: TOTAL DEPRECIATION | K32: Yr 1 | L32: Yr 2
K33: =SUM(I13+K30) -> 0 | L33: =SUM(J13+L30) -> 0

Sheet Business Loans
A1: Financial Plan of | B1: ='Set Up Details'!C2 -> Test1
A4: Loan 1
A5: Name of lender
A6: Start Date (dd/mm/yy)
A7: Date of Loan (dd/mm/yy)
A8: Estimated Loan
A9: Stamp Duty
A10: Application Fees
A11: Other Loan Costs
A12: Total Loan AMOUNT | B12: =SUM(B8:B11) -> 0
A13: Interest Rate % | B13: 0.03 | D13: Total Interest | E13: =ROUND(SUM(E14-B12),0) -> 0 | G13: Interest p/mth | H13: 0
A14: Loan Term (years) | B14: 2 | D14: Total Amount Owing | E14: =ROUND(SUM(H14*B15*B14),0) -> 0 | G14: Monthly Repayments $ | H14: =ROUND(PMT(B13/B15,B16,-B12),0) -> 0
A15: Repayment periods per year | B15: 12 | D15: Total repaid per year | E15: =ROUND(SUM(H14*B15),0) -> 0 | G15: Actual Interest Paid Y1 | H15: =ROUND(IF(A18>12,0,((12-A18)*H13)),0) -> 0 | I15: =IF(B7<B6," ",(12-A18)) -> 12
A16: Loan Terms (months) | B16: =SUM(B14*B15) -> 24 | D16: Repaid by | E16: 30/2/2028 | G16: Actual Interest Paid Y2 | H16: =ROUND(IF(I16<12,(I16*H13),IF(I16>=12,(12*H13))),0) -> 0 | I16: =SUM(B16-I15) -> 12
A17: Month
A18: =MONTH(B7)-MONTH(B6)+12*(YEAR(B7)-YEAR(B6)) -> 0
A20: Note: This is a basic loan calculator, and simply spreads repayments evenly over the period of the loan.
A22: Loan 2
A23: Name of lender
A24: Start Date (dd/mm/yy)
A25: Date of Loan (dd/mm/yy)
A26: Estimated Loan
A27: Stamp Duty
A28: Application Fees
A29: Other Loan Costs
A30: Total Loan AMOUNT | B30: =SUM(B26:B29) -> 0 | D30: Total Interest | E30: =ROUND(SUM(E31-B30),0) -> 0 | G30: Interest p/mth | H30: =ROUND(SUM(E30/B34),0) -> 0
A31: Interest Rate % | B31: 0.06 | D31: Total Amount Owing | E31: =ROUND(SUM(H31*B33*B32),0) -> 0 | G31: Monthly Repayments $ | H31: =ROUND(PMT(B31/B33,B34,-B30),0) -> 0
A32: Loan Term (years) | B32: 2 | D32: Total repaid per year | E32: =ROUND(SUM(H31*B33),0) -> 0 | G32: Actual Interest Paid Y1 | H32: =ROUND(IF(A36>12,0,((12-A36)*H30)),0) -> 0 | I32: =IF(B25<B24," ",(12-A36)) -> 12
A33: Repayment periods per year | B33: 12 | D33: Repaid by | E33: =(B25+(B32*365.25)) -> 730.5 | G33: Actual Interest Paid Y2 | H33: =ROUND(IF(I33<12,(I33*H30),IF(I33>=12,(12*H30))),0) -> 0 | I33: =SUM(B34-I32) -> 12
A34: Loan Terms (months) | B34: =SUM(B32*B33) -> 24
A35: Month
A36: =MONTH(B25)-MONTH(B24)+12*(YEAR(B25)-YEAR(B24)) -> 0
A38: Note: This is a basic loan calculator, and simply spreads repayments evenly over the period of the loan.

Sheet Marketing Action Plan Year 1
A1: Financial plan of | B1: ='Set Up Details'!C2 -> Test1
A2: MARKETING ACTION PLAN - YEAR 1 | P2: How will you monitor return on investment (ROI) (where applicable)
A4: Activity | C4: ='Personal Cash Flow Budget Y1'!B4 -> Jan | D4: ='Personal Cash Flow Budget Y1'!C4 -> Feb | E4: ='Personal Cash Flow Budget Y1'!D4 -> Mar | F4: ='Personal Cash Flow Budget Y1'!E4 -> Apr | G4: ='Personal Cash Flow Budget Y1'!F4 -> May | H4: ='Personal Cash Flow Budget Y1'!G4 -> Jun | I4: ='Personal Cash Flow Budget Y1'!H4 -> Jul | J4: ='Personal Cash Flow Budget Y1'!I4 -> Aug | ... N4: ='Personal Cash Flow Budget Y1'!M4 -> Dec | O4: Total
A6: Example only: Flyers | B6: Cost $ / When | C6: 400 | I6: 400 | O6: =SUM(C6:N6) -> 800
A7: Example only: Mailbox Drops | B7: Cost $ / When | D7: 0 | F7: 0 | H7: 0 | J7: 0 | L7: 0 | N7: 0 | O7: =SUM(C7:N7) -> 0
A9: Logo Design | B9: Cost $ / When | O9: =SUM(C9:N9) -> 0
A10: Business Cards | B10: Cost $ / When | O10: =SUM(C10:N10) -> 0
A11: Copyrighting | B11: Cost $ / When | O11: =SUM(C11:N11) -> 0
A12: Photograpy / Image / Music Licenses | B12: Cost $ / When | O12: =SUM(C12:N12) -> 0
A13: Logo / Letterhead / Stationery | B13: Cost $ / When | O13: =SUM(C13:N13) -> 0
A14: Flyers | B14: Cost $ / When | O14: =SUM(C14:N14) -> 0
A15: Signage | B15: Cost $ / When | O15: =SUM(C15:N15) -> 0
A16: Mailouts / Letterbox Drops | B16: Cost $ / When | O16: =SUM(C16:N16) -> 0
A17: Folio updates | B17: Cost $ / When | O17: =SUM(C17:N17) -> 0
A18: Database - develop / purchase | B18: Cost $ / When | O18: =SUM(C18:N18) -> 0
A19: Special Event: Planning / Running | B19: Cost $ / When | O19: =SUM(C19:N19) -> 0
A20: Networking | B20: Cost $ / When | O20: =SUM(C20:N20) -> 0
... A36: Uniform | B36: Cost $ / When | O36: =SUM(C36:N36) -> 0
B37: Cost $ / When | O37: =SUM(C37:N37) -> 0
B38: Cost $ / When | O38: =SUM(C38:N38) -> 0
B39: Cost $ / When | O39: =SUM(C39:N39) -> 0
A40: TOTAL COST | C40: =ROUND((C9+C10+C11+C12+C13+C14+C15+C16+C17+C18+C19+C20+C21+C22+C23+C24+C25+C26+C27+C28+C29+C30+C31+C32+C33+C34+C35+C36+C37+C38+C39),0) -> 0 | D40: =ROUND((D9+D10+D11+D12+D13+D14+D15+D16+D17+D18+D19+D20+D21+D22+D23+D24+D25+D26+D27+D28+D29+D30+D31+D32+D33+D34+D35+D36+D37+D38+D39),0) -> 0 | E40: =ROUND((E9+E10+E11+E12+E13+E14+E15+E16+E17+E18+E19+E20+E21+E22+E23+E24+E25+E26+E27+E28+E29+E30+E31+E32+E33+E34+E35+E36+E37+E38+E39),0) -> 0 | F40: =ROUND((F9+F10+F11+F12+F13+F14+F15+F16+F17+F18+F19+F20+F21+F22+F23+F24+F25+F26+F27+F28+F29+F30+F31+F32+F33+F34+F35+F36+F37+F38+F39),0) -> 0 | G40: =ROUND((G9+G10+G11+G12+G13+G14+G15+G16+G17+G18+G19+G20+G21+G22+G23+G24+G25+G26+G27+G28+G29+G30+G31+G32+G33+G34+G35+G36+G37+G38+G39),0) -> 0 | H40: =ROUND((H9+H10+H11+H12+H13+H14+H15+H16+H17+H18+H19+H20+H21+H22+H23+H24+H25+H26+H27+H28+H29+H30+H31+H32+H33+H34+H35+H36+H37+H38+H39),0) -> 0 | I40: =ROUND((I9+I10+I11+I12+I13+I14+I15+I16+I17+I18+I19+I20+I21+I22+I23+I24+I25+I26+I27+I28+I29+I30+I31+I32+I33+I34+I35+I36+I37+I38+I39),0) -> 0 | J40: =ROUND((J9+J10+J11+J12+J13+J14+J15+J16+J17+J18+J19+J20+J21+J22+J23+J24+J25+J26+J27+J28+J29+J30+J31+J32+J33+J34+J35+J36+J37+J38+J39),0) -> 0 | ... N40: =ROUND((N9+N10+N11+N12+N13+N14+N15+N16+N17+N18+N19+N20+N21+N22+N23+N24+N25+N26+N27+N28+N29+N30+N31+N32+N33+N34+N35+N36+N37+N38+N39),0) -> 0 | O40: =SUM(O9:O39) -> 0

Sheet Marketing Action Plan Year 2
A1: Financial plan of | B1: ='Set Up Details'!C2 -> Test1
A2: MARKETING ACTION PLAN - YEAR 2 | P2: How will you monitor return on investment (ROI) (where applicable)
A4: Activity | C4: ='Personal Cash Flow Budget Y1'!B4 -> Jan | D4: ='Personal Cash Flow Budget Y1'!C4 -> Feb | E4: ='Personal Cash Flow Budget Y1'!D4 -> Mar | F4: ='Personal Cash Flow Budget Y1'!E4 -> Apr | G4: ='Personal Cash Flow Budget Y1'!F4 -> May | H4: ='Personal Cash Flow Budget Y1'!G4 -> Jun | I4: ='Personal Cash Flow Budget Y1'!H4 -> Jul | J4: ='Personal Cash Flow Budget Y1'!I4 -> Aug | ... N4: ='Personal Cash Flow Budget Y1'!M4 -> Dec | O4: Total
A6: Example only: Flyers | B6: Cost $ / When | C6: 400 | I6: 400 | O6: =SUM(C6:N6) -> 800
A7: Example only: Mailbox Drops | B7: Cost $ / When | D7: 0 | F7: 0 | H7: 0 | J7: 0 | L7: 0 | N7: 0 | O7: =SUM(C7:N7) -> 0
A9: Logo Design | B9: Cost $ / When | O9: =SUM(C9:N9) -> 0
A10: Business Cards | B10: Cost $ / When | O10: =SUM(C10:N10) -> 0
A11: Copyrighting | B11: Cost $ / When | O11: =SUM(C11:N11) -> 0
A12: Photograpy / Image / Music Licenses | B12: Cost $ / When | O12: =SUM(C12:N12) -> 0
A13: Logo / Letterhead / Stationery | B13: Cost $ / When | O13: =SUM(C13:N13) -> 0
A14: Flyers | B14: Cost $ / When | O14: =SUM(C14:N14) -> 0
A15: Signage | B15: Cost $ / When | O15: =SUM(C15:N15) -> 0
A16: Mailouts / Letterbox Drops | B16: Cost $ / When | O16: =SUM(C16:N16) -> 0
A17: Folio updates | B17: Cost $ / When | O17: =SUM(C17:N17) -> 0
A18: Database - develop / purchase | B18: Cost $ / When | O18: =SUM(C18:N18) -> 0
A19: Special Event: Planning / Running | B19: Cost $ / When | O19: =SUM(C19:N19) -> 0
A20: Networking | B20: Cost $ / When | O20: =SUM(C20:N20) -> 0
... A36: Uniform | B36: Cost $ / When | O36: =SUM(C36:N36) -> 0
B37: Cost $ / When | O37: =SUM(C37:N37) -> 0
B38: Cost $ / When | O38: =SUM(C38:N38) -> 0
B39: Cost $ / When | O39: =SUM(C39:N39) -> 0
A40: TOTAL COST | C40: =ROUND((C9+C10+C11+C12+C13+C14+C15+C16+C17+C18+C19+C20+C21+C22+C23+C24+C25+C26+C27+C28+C29+C30+C31+C32+C33+C34+C35+C36+C37+C38+C39),0) -> 0 | D40: =ROUND((D9+D10+D11+D12+D13+D14+D15+D16+D17+D18+D19+D20+D21+D22+D23+D24+D25+D26+D27+D28+D29+D30+D31+D32+D33+D34+D35+D36+D37+D38+D39),0) -> 0 | E40: =ROUND((E9+E10+E11+E12+E13+E14+E15+E16+E17+E18+E19+E20+E21+E22+E23+E24+E25+E26+E27+E28+E29+E30+E31+E32+E33+E34+E35+E36+E37+E38+E39),0) -> 0 | F40: =ROUND((F9+F10+F11+F12+F13+F14+F15+F16+F17+F18+F19+F20+F21+F22+F23+F24+F25+F26+F27+F28+F29+F30+F31+F32+F33+F34+F35+F36+F37+F38+F39),0) -> 0 | G40: =ROUND((G9+G10+G11+G12+G13+G14+G15+G16+G17+G18+G19+G20+G21+G22+G23+G24+G25+G26+G27+G28+G29+G30+G31+G32+G33+G34+G35+G36+G37+G38+G39),0) -> 0 | H40: =ROUND((H9+H10+H11+H12+H13+H14+H15+H16+H17+H18+H19+H20+H21+H22+H23+H24+H25+H26+H27+H28+H29+H30+H31+H32+H33+H34+H35+H36+H37+H38+H39),0) -> 0 | I40: =ROUND((I9+I10+I11+I12+I13+I14+I15+I16+I17+I18+I19+I20+I21+I22+I23+I24+I25+I26+I27+I28+I29+I30+I31+I32+I33+I34+I35+I36+I37+I38+I39),0) -> 0 | J40: =ROUND((J9+J10+J11+J12+J13+J14+J15+J16+J17+J18+J19+J20+J21+J22+J23+J24+J25+J26+J27+J28+J29+J30+J31+J32+J33+J34+J35+J36+J37+J38+J39),0) -> 0 | ... N40: =ROUND((N9+N10+N11+N12+N13+N14+N15+N16+N17+N18+N19+N20+N21+N22+N23+N24+N25+N26+N27+N28+N29+N30+N31+N32+N33+N34+N35+N36+N37+N38+N39),0) -> 0 | O40: =SUM(O9:O39) -> 0

Sheet Marketing Action Plan Year 3
A1: Financial plan of | B1: ='Set Up Details'!C2 -> Test1
A2: MARKETING ACTION PLAN - YEAR 3 | P2: How will you monitor return on investment (ROI) (where applicable)
A4: Activity | C4: ='Personal Cash Flow Budget Y1'!B4 -> Jan | D4: ='Personal Cash Flow Budget Y1'!C4 -> Feb | E4: ='Personal Cash Flow Budget Y1'!D4 -> Mar | F4: ='Personal Cash Flow Budget Y1'!E4 -> Apr | G4: ='Personal Cash Flow Budget Y1'!F4 -> May | H4: ='Personal Cash Flow Budget Y1'!G4 -> Jun | I4: ='Personal Cash Flow Budget Y1'!H4 -> Jul | J4: ='Personal Cash Flow Budget Y1'!I4 -> Aug | ... N4: ='Personal Cash Flow Budget Y1'!M4 -> Dec | O4: Total
A6: Example only: Flyers | B6: Cost $ / When | C6: 400 | I6: 400 | O6: =SUM(C6:N6) -> 800
A7: Example only: Mailbox Drops | B7: Cost $ / When | D7: 0 | F7: 0 | H7: 0 | J7: 0 | L7: 0 | N7: 0 | O7: =SUM(C7:N7) -> 0
A9: Logo Design | B9: Cost $ / When | O9: =SUM(C9:N9) -> 0
A10: Business Cards | B10: Cost $ / When | O10: =SUM(C10:N10) -> 0
A11: Copyrighting | B11: Cost $ / When | O11: =SUM(C11:N11) -> 0
A12: Photograpy / Image / Music Licenses | B12: Cost $ / When | O12: =SUM(C12:N12) -> 0
A13: Logo / Letterhead / Stationery | B13: Cost $ / When | O13: =SUM(C13:N13) -> 0
A14: Flyers | B14: Cost $ / When | O14: =SUM(C14:N14) -> 0
A15: Signage | B15: Cost $ / When | O15: =SUM(C15:N15) -> 0
A16: Mailouts / Letterbox Drops | B16: Cost $ / When | O16: =SUM(C16:N16) -> 0
A17: Folio updates | B17: Cost $ / When | O17: =SUM(C17:N17) -> 0
A18: Database - develop / purchase | B18: Cost $ / When | O18: =SUM(C18:N18) -> 0
A19: Special Event: Planning / Running | B19: Cost $ / When | O19: =SUM(C19:N19) -> 0
A20: Networking | B20: Cost $ / When | O20: =SUM(C20:N20) -> 0
... A36: Uniform | B36: Cost $ / When | O36: =SUM(C36:N36) -> 0
B37: Cost $ / When | O37: =SUM(C37:N37) -> 0
B38: Cost $ / When | O38: =SUM(C38:N38) -> 0
B39: Cost $ / When | O39: =SUM(C39:N39) -> 0
A40: TOTAL COST | C40: =ROUND((C9+C10+C11+C12+C13+C14+C15+C16+C17+C18+C19+C20+C21+C22+C23+C24+C25+C26+C27+C28+C29+C30+C31+C32+C33+C34+C35+C36+C37+C38+C39),0) -> 0 | D40: =ROUND((D9+D10+D11+D12+D13+D14+D15+D16+D17+D18+D19+D20+D21+D22+D23+D24+D25+D26+D27+D28+D29+D30+D31+D32+D33+D34+D35+D36+D37+D38+D39),0) -> 0 | E40: =ROUND((E9+E10+E11+E12+E13+E14+E15+E16+E17+E18+E19+E20+E21+E22+E23+E24+E25+E26+E27+E28+E29+E30+E31+E32+E33+E34+E35+E36+E37+E38+E39),0) -> 0 | F40: =ROUND((F9+F10+F11+F12+F13+F14+F15+F16+F17+F18+F19+F20+F21+F22+F23+F24+F25+F26+F27+F28+F29+F30+F31+F32+F33+F34+F35+F36+F37+F38+F39),0) -> 0 | G40: =ROUND((G9+G10+G11+G12+G13+G14+G15+G16+G17+G18+G19+G20+G21+G22+G23+G24+G25+G26+G27+G28+G29+G30+G31+G32+G33+G34+G35+G36+G37+G38+G39),0) -> 0 | H40: =ROUND((H9+H10+H11+H12+H13+H14+H15+H16+H17+H18+H19+H20+H21+H22+H23+H24+H25+H26+H27+H28+H29+H30+H31+H32+H33+H34+H35+H36+H37+H38+H39),0) -> 0 | I40: =ROUND((I9+I10+I11+I12+I13+I14+I15+I16+I17+I18+I19+I20+I21+I22+I23+I24+I25+I26+I27+I28+I29+I30+I31+I32+I33+I34+I35+I36+I37+I38+I39),0) -> 0 | J40: =ROUND((J9+J10+J11+J12+J13+J14+J15+J16+J17+J18+J19+J20+J21+J22+J23+J24+J25+J26+J27+J28+J29+J30+J31+J32+J33+J34+J35+J36+J37+J38+J39),0) -> 0 | ... N40: =ROUND((N9+N10+N11+N12+N13+N14+N15+N16+N17+N18+N19+N20+N21+N22+N23+N24+N25+N26+N27+N28+N29+N30+N31+N32+N33+N34+N35+N36+N37+N38+N39),0) -> 0 | O40: =SUM(O9:O39) -> 0

Sheet Sales Details
A1: Financial plan of | C1: ='Set Up Details'!C2 -> Test1
A2: Sales details | J2: Payment Method
A3: Sales Categories | C3: Selling Price (incl GST, if applicable) | D3: Cost of Goods Sold | E3: Product Gross Margin % | F3: Trading Terms | J3: Average percentage of sales to be paid using merchant facilities
F4: Percentage of sale to be received in | J4: % of sales | M4: Merchant Fee %
F5: Immediate | G5: 1 month after sale | H5: 2 months after sale | I5: 3 months after sale | J5: 0.9 | M5: 1.8
A6: Test-category-1 | C6: 10000 | D6: 1000 | E6: =IF(OR(ISBLANK(C6),ISBLANK(D6)),"",(C6-D6)/C6) -> 0.9 | F6: 0.2 | G6: 0.2 | H6: 0.2 | I6: 0.2 | J6: =IF(ISBLANK(A6)," ",(IF(SUM(F6:I6)=100%," ","F, G, H & I Must Add-Up To Make 100%"))) -> F, G, H & I Must Add-Up To Make 100%
A7: Test-category-2 | C7: 5000 | D7: 500 | E7: =IF(OR(ISBLANK(C7),ISBLANK(D7)),"",(C7-D7)/C7) -> 0.9 | F7: 1 | J7: =IF(ISBLANK(A7)," ",(IF(SUM(F7:I7)=100%," ","F, G, H & I Must Add to 100%")))
A8: Test-category-3 | C8: 4000 | D8: 400 | E8: =IF(OR(ISBLANK(C8),ISBLANK(D8)),"",(C8-D8)/C8) -> 0.9 | F8: 0.5 | G8: 0.5 | J8: =IF(ISBLANK(A8)," ",(IF(SUM(F8:I8)=100%," ","F, G, H & I Must Add to 100%")))
D9: 0 | E9: =IF(OR(ISBLANK(C9),ISBLANK(D9)),"",(C9-D9)/C9) | J9: =IF(ISBLANK(A9)," ",(IF(SUM(F9:I9)=100%," ","F, G, H & I Must Add to 100%")))
D10: 0 | E10: =IF(OR(ISBLANK(C10),ISBLANK(D10)),"",(C10-D10)/C10) | J10: =IF(ISBLANK(A10)," ",(IF(SUM(F10:I10)=100%," ","F, G, H & I Must Add to 100%")))
D11: 0 | E11: =IF(OR(ISBLANK(C11),ISBLANK(D11)),"",(C11-D11)/C11) | J11: =IF(ISBLANK(A11)," ",(IF(SUM(F11:I11)=100%," ","F, G, H & I Must Add to 100%")))
D12: 0 | E12: =IF(OR(ISBLANK(C12),ISBLANK(D12)),"",(C12-D12)/C12) | J12: =IF(ISBLANK(A12)," ",(IF(SUM(F12:I12)=100%," ","F, G, H & I Must Add to 100%")))
D13: 0 | E13: =IF(OR(ISBLANK(C13),ISBLANK(D13)),"",(C13-D13)/C13) | J13: =IF(ISBLANK(A13)," ",(IF(SUM(F13:I13)=100%," ","F, G, H & I Must Add to 100%")))
D14: 0 | E14: =IF(OR(ISBLANK(C14),ISBLANK(D14)),"",(C14-D14)/C14) | J14: =IF(ISBLANK(A14)," ",(IF(SUM(F14:I14)=100%," ","F, G, H & I Must Add to 100%")))
D15: 0 | E15: =IF(OR(ISBLANK(C15),ISBLANK(D15)),"",(C15-D15)/C15) | J15: =IF(ISBLANK(A15)," ",(IF(SUM(F15:I15)=100%," ","F, G, H & I Must Add to 100%")))
D16: 0 | E16: =IF(OR(ISBLANK(C16),ISBLANK(D16)),"",(C16-D16)/C16) | J16: =IF(ISBLANK(A16)," ",(IF(SUM(F16:I16)=100%," ","F, G, H & I Must Add to 100%")))
D17: 0 | E17: =IF(OR(ISBLANK(C17),ISBLANK(D17)),"",(C17-D17)/C17) | J17: =IF(ISBLANK(A17)," ",(IF(SUM(F17:I17)=100%," ","F, G, H & I Must Add to 100%")))
D18: 0 | E18: =IF(OR(ISBLANK(C18),ISBLANK(D18)),"",(C18-D18)/C18) | J18: =IF(ISBLANK(A18)," ",(IF(SUM(F18:I18)=100%," ","F, G, H & I Must Add to 100%")))
D19: 0 | E19: =IF(OR(ISBLANK(C19),ISBLANK(D19)),"",(C19-D19)/C19) | J19: =IF(ISBLANK(A19)," ",(IF(SUM(F19:I19)=100%," ","F, G, H & I Must Add to 100%")))
D20: 0 | E20: =IF(OR(ISBLANK(C20),ISBLANK(D20)),"",(C20-D20)/C20) | J20: =IF(ISBLANK(A20)," ",(IF(SUM(F20:I20)=100%," ","F, G, H & I Must Add to 100%")))
... D30: 0 | E30: =IF(OR(ISBLANK(C30),ISBLANK(D30)),"",(C30-D30)/C30) | J30: =IF(ISBLANK(A30)," ",(IF(SUM(F30:I30)=100%," ","F, G, H & I Must Add to 100%")))

Sheet Sales Forecast Year 1
A1: Financial plan of | C1: ='Set Up Details'!C2 -> Test1
A3: Sales Forecast Year 1
A6: Sales Categories | C6: Unit of sale | D6: ='Tables and Calculations'!B2 -> Jan | E6: ='Tables and Calculations'!C2 -> Feb | F6: ='Tables and Calculations'!D2 -> Mar | G6: ='Tables and Calculations'!E2 -> Apr | H6: ='Tables and Calculations'!F2 -> May | I6: ='Tables and Calculations'!G2 -> Jun | J6: ='Tables and Calculations'!H2 -> Jul | K6: ='Tables and Calculations'!I2 -> Aug | ... O6: ='Tables and Calculations'!M2 -> Dec | P6: Total | Q6: % of sales volume
D7: Projected volume of sales per month | S7: Yes
A8: =IF(ISBLANK('Sales Details'!A6)," ",('Sales Details'!A6)) -> Test-category-1 | P8: =SUM(D8:O8) -> 0 | Q8: =IF(ISERROR(P8/$P$23),0,P8/$P$23) -> 0 | S8: No
A9: =IF(ISBLANK('Sales Details'!A7)," ",('Sales Details'!A7)) -> Test-category-2 | P9: =SUM(D9:O9) -> 0 | Q9: =IF(ISERROR(P9/$P$23),0,P9/$P$23) -> 0
A10: =IF(ISBLANK('Sales Details'!A8)," ",('Sales Details'!A8)) -> Test-category-3 | P10: =SUM(D10:O10) -> 0 | Q10: =IF(ISERROR(P10/$P$23),0,P10/$P$23) -> 0
A11: =IF(ISBLANK('Sales Details'!A9)," ",('Sales Details'!A9)) | P11: =SUM(D11:O11) -> 0 | Q11: =IF(ISERROR(P11/$P$23),0,P11/$P$23) -> 0
A12: =IF(ISBLANK('Sales Details'!A10)," ",('Sales Details'!A10)) | P12: =SUM(D12:O12) -> 0 | Q12: =IF(ISERROR(P12/$P$23),0,P12/$P$23) -> 0
A13: =IF(ISBLANK('Sales Details'!A11)," ",('Sales Details'!A11)) | P13: =SUM(D13:O13) -> 0 | Q13: =IF(ISERROR(P13/$P$23),0,P13/$P$23) -> 0
A14: =IF(ISBLANK('Sales Details'!A12)," ",('Sales Details'!A12)) | P14: =SUM(D14:O14) -> 0 | Q14: =IF(ISERROR(P14/$P$23),0,P14/$P$23) -> 0
A15: =IF(ISBLANK('Sales Details'!A13)," ",('Sales Details'!A13)) | P15: =SUM(D15:O15) -> 0 | Q15: =IF(ISERROR(P15/$P$23),0,P15/$P$23) -> 0
A16: =IF(ISBLANK('Sales Details'!A14)," ",('Sales Details'!A14)) | P16: =SUM(D16:O16) -> 0 | Q16: =IF(ISERROR(P16/$P$23),0,P16/$P$23) -> 0
A17: =IF(ISBLANK('Sales Details'!A15)," ",('Sales Details'!A15)) | P17: =SUM(D17:O17) -> 0 | Q17: =IF(ISERROR(P17/$P$23),0,P17/$P$23) -> 0
A18: =IF(ISBLANK('Sales Details'!A16)," ",('Sales Details'!A16)) | P18: =SUM(D18:O18) -> 0 | Q18: =IF(ISERROR(P18/$P$23),0,P18/$P$23) -> 0
A19: =IF(ISBLANK('Sales Details'!A17)," ",('Sales Details'!A17)) | P19: =SUM(D19:O19) -> 0 | Q19: =IF(ISERROR(P19/$P$23),0,P19/$P$23) -> 0
A20: =IF(ISBLANK('Sales Details'!A18)," ",('Sales Details'!A18)) | P20: =SUM(D20:O20) -> 0 | Q20: =IF(ISERROR(P20/$P$23),0,P20/$P$23) -> 0
... A22: =IF(ISBLANK('Sales Details'!A20)," ",('Sales Details'!A20)) | P22: =SUM(D22:O22) -> 0 | Q22: =IF(ISERROR(P22/$P$23),0,P22/$P$23) -> 0
A23: Total volume | D23: =SUM(D8:D22) -> 0 | E23: =SUM(E8:E22) -> 0 | F23: =SUM(F8:F22) -> 0 | G23: =SUM(G8:G22) -> 0 | H23: =SUM(H8:H22) -> 0 | I23: =SUM(I8:I22) -> 0 | J23: =SUM(J8:J22) -> 0 | K23: =SUM(K8:K22) -> 0 | ... P23: =SUM(P8:P22) -> 0 | Q23: =Q8+Q9+Q10+Q11+Q12+Q13+Q14+Q15+Q16+Q17+Q18+Q19+Q20+Q21+Q22 -> 0
A25: Sales categories | B25: Taxable sale | C25: Price | D25: =D6 -> Jan | E25: =E6 -> Feb | F25: =F6 -> Mar | G25: =G6 -> Apr | H25: =H6 -> May | I25: =I6 -> Jun | J25: =J6 -> Jul | K25: =K6 -> Aug | ... P25: =P6 -> Total | Q25: % of sales revenue
A26: =IF(ISBLANK('Sales Details'!A6)," ",('Sales Details'!A6)) -> Test-category-1 | C26: ='Sales Details'!C6 -> 10000 | D26: =INT($C26*D8) -> 0 | E26: =INT($C26*E8) -> 0 | F26: =INT($C26*F8) -> 0 | G26: =INT($C26*G8) -> 0 | H26: =INT($C26*H8) -> 0 | I26: =INT($C26*I8) -> 0 | J26: =INT($C26*J8) -> 0 | K26: =INT($C26*K8) -> 0 | ... O26: =INT($C26*O8) -> 0 | P26: =SUM(D26:O26) -> 0 | Q26: =IF(ISERROR(P26/$P$41),0,P26/$P$41) -> 0
A27: =IF(ISBLANK('Sales Details'!A7)," ",('Sales Details'!A7)) -> Test-category-2 | C27: ='Sales Details'!C7 -> 5000 | D27: =INT($C27*D9) -> 0 | E27: =INT($C27*E9) -> 0 | F27: =INT($C27*F9) -> 0 | G27: =INT($C27*G9) -> 0 | H27: =INT($C27*H9) -> 0 | I27: =INT($C27*I9) -> 0 | J27: =INT($C27*J9) -> 0 | K27: =INT($C27*K9) -> 0 | ... O27: =INT($C27*O9) -> 0 | P27: =SUM(D27:O27) -> 0 | Q27: =IF(ISERROR(P27/$P$41),0,P27/$P$41) -> 0
A28: =IF(ISBLANK('Sales Details'!A8)," ",('Sales Details'!A8)) -> Test-category-3 | C28: ='Sales Details'!C8 -> 4000 | D28: =INT($C28*D10) -> 0 | E28: =INT($C28*E10) -> 0 | F28: =INT($C28*F10) -> 0 | G28: =INT($C28*G10) -> 0 | H28: =INT($C28*H10) -> 0 | I28: =INT($C28*I10) -> 0 | J28: =INT($C28*J10) -> 0 | K28: =INT($C28*K10) -> 0 | ... O28: =INT($C28*O10) -> 0 | P28: =SUM(D28:O28) -> 0 | Q28: =IF(ISERROR(P28/$P$41),0,P28/$P$41) -> 0
A29: =IF(ISBLANK('Sales Details'!A9)," ",('Sales Details'!A9)) | C29: ='Sales Details'!C9 -> 0 | D29: =INT($C29*D11) -> 0 | E29: =INT($C29*E11) -> 0 | F29: =INT($C29*F11) -> 0 | G29: =INT($C29*G11) -> 0 | H29: =INT($C29*H11) -> 0 | I29: =INT($C29*I11) -> 0 | J29: =INT($C29*J11) -> 0 | K29: =INT($C29*K11) -> 0 | ... O29: =INT($C29*O11) -> 0 | P29: =SUM(D29:O29) -> 0 | Q29: =IF(ISERROR(P29/$P$41),0,P29/$P$41) -> 0
A30: =IF(ISBLANK('Sales Details'!A10)," ",('Sales Details'!A10)) | C30: ='Sales Details'!C10 -> 0 | D30: =INT($C30*D12) -> 0 | E30: =INT($C30*E12) -> 0 | F30: =INT($C30*F12) -> 0 | G30: =INT($C30*G12) -> 0 | H30: =INT($C30*H12) -> 0 | I30: =INT($C30*I12) -> 0 | J30: =INT($C30*J12) -> 0 | K30: =INT($C30*K12) -> 0 | ... O30: =INT($C30*O12) -> 0 | P30: =SUM(D30:O30) -> 0 | Q30: =IF(ISERROR(P30/$P$41),0,P30/$P$41) -> 0
A31: =IF(ISBLANK('Sales Details'!A11)," ",('Sales Details'!A11)) | C31: ='Sales Details'!C11 -> 0 | D31: =INT($C31*D13) -> 0 | E31: =INT($C31*E13) -> 0 | F31: =INT($C31*F13) -> 0 | G31: =INT($C31*G13) -> 0 | H31: =INT($C31*H13) -> 0 | I31: =INT($C31*I13) -> 0 | J31: =INT($C31*J13) -> 0 | K31: =INT($C31*K13) -> 0 | ... O31: =INT($C31*O13) -> 0 | P31: =SUM(D31:O31) -> 0 | Q31: =IF(ISERROR(P31/$P$41),0,P31/$P$41) -> 0
A32: =IF(ISBLANK('Sales Details'!A12)," ",('Sales Details'!A12)) | C32: ='Sales Details'!C12 -> 0 | D32: =INT($C32*D14) -> 0 | E32: =INT($C32*E14) -> 0 | F32: =INT($C32*F14) -> 0 | G32: =INT($C32*G14) -> 0 | H32: =INT($C32*H14) -> 0 | I32: =INT($C32*I14) -> 0 | J32: =INT($C32*J14) -> 0 | K32: =INT($C32*K14) -> 0 | ... O32: =INT($C32*O14) -> 0 | P32: =SUM(D32:O32) -> 0 | Q32: =IF(ISERROR(P32/$P$41),0,P32/$P$41) -> 0
A33: =IF(ISBLANK('Sales Details'!A13)," ",('Sales Details'!A13)) | C33: ='Sales Details'!C13 -> 0 | D33: =INT($C33*D15) -> 0 | E33: =INT($C33*E15) -> 0 | F33: =INT($C33*F15) -> 0 | G33: =INT($C33*G15) -> 0 | H33: =INT($C33*H15) -> 0 | I33: =INT($C33*I15) -> 0 | J33: =INT($C33*J15) -> 0 | K33: =INT($C33*K15) -> 0 | ... O33: =INT($C33*O15) -> 0 | P33: =SUM(D33:O33) -> 0 | Q33: =IF(ISERROR(P33/$P$41),0,P33/$P$41) -> 0
A34: =IF(ISBLANK('Sales Details'!A14)," ",('Sales Details'!A14)) | C34: ='Sales Details'!C14 -> 0 | D34: =INT($C34*D16) -> 0 | E34: =INT($C34*E16) -> 0 | F34: =INT($C34*F16) -> 0 | G34: =INT($C34*G16) -> 0 | H34: =INT($C34*H16) -> 0 | I34: =INT($C34*I16) -> 0 | J34: =INT($C34*J16) -> 0 | K34: =INT($C34*K16) -> 0 | M34: =INT($C34*M16) -> 0 | N34: =INT($C34*N16) -> 0 | O34: =INT($C34*O16) -> 0 | P34: =SUM(D34:O34) -> 0 | Q34: =IF(ISERROR(P34/$P$41),0,P34/$P$41) -> 0
A35: =IF(ISBLANK('Sales Details'!A15)," ",('Sales Details'!A15)) | C35: ='Sales Details'!C15 -> 0 | D35: =INT($C35*D17) -> 0 | E35: =INT($C35*E17) -> 0 | F35: =INT($C35*F17) -> 0 | G35: =INT($C35*G17) -> 0 | H35: =INT($C35*H17) -> 0 | I35: =INT($C35*I17) -> 0 | J35: =INT($C35*J17) -> 0 | K35: =INT($C35*K17) -> 0 | ... O35: =INT($C35*O17) -> 0 | P35: =SUM(D35:O35) -> 0 | Q35: =IF(ISERROR(P35/$P$41),0,P35/$P$41) -> 0
A36: =IF(ISBLANK('Sales Details'!A16)," ",('Sales Details'!A16)) | C36: ='Sales Details'!C16 -> 0 | D36: =INT($C36*D18) -> 0 | E36: =INT($C36*E18) -> 0 | F36: =INT($C36*F18) -> 0 | G36: =INT($C36*G18) -> 0 | H36: =INT($C36*H18) -> 0 | I36: =INT($C36*I18) -> 0 | J36: =INT($C36*J18) -> 0 | K36: =INT($C36*K18) -> 0 | ... O36: =INT($C36*O18) -> 0 | P36: =SUM(D36:O36) -> 0 | Q36: =IF(ISERROR(P36/$P$41),0,P36/$P$41) -> 0
A37: =IF(ISBLANK('Sales Details'!A17)," ",('Sales Details'!A17)) | C37: ='Sales Details'!C17 -> 0 | D37: =INT($C37*D19) -> 0 | E37: =INT($C37*E19) -> 0 | F37: =INT($C37*F19) -> 0 | G37: =INT($C37*G19) -> 0 | H37: =INT($C37*H19) -> 0 | I37: =INT($C37*I19) -> 0 | J37: =INT($C37*J19) -> 0 | K37: =INT($C37*K19) -> 0 | ... O37: =INT($C37*O19) -> 0 | P37: =SUM(D37:O37) -> 0 | Q37: =IF(ISERROR(P37/$P$41),0,P37/$P$41) -> 0
A38: =IF(ISBLANK('Sales Details'!A18)," ",('Sales Details'!A18)) | C38: ='Sales Details'!C18 -> 0 | D38: =INT($C38*D20) -> 0 | E38: =INT($C38*E20) -> 0 | F38: =INT($C38*F20) -> 0 | G38: =INT($C38*G20) -> 0 | H38: =INT($C38*H20) -> 0 | I38: =INT($C38*I20) -> 0 | J38: =INT($C38*J20) -> 0 | K38: =INT($C38*K20) -> 0 | ... O38: =INT($C38*O20) -> 0 | P38: =SUM(D38:O38) -> 0 | Q38: =IF(ISERROR(P38/$P$41),0,P38/$P$41) -> 0
A39: =IF(ISBLANK('Sales Details'!A19)," ",('Sales Details'!A19)) | C39: ='Sales Details'!C19 -> 0 | D39: =INT($C39*D21) -> 0 | E39: =INT($C39*E21) -> 0 | F39: =INT($C39*F21) -> 0 | G39: =INT($C39*G21) -> 0 | H39: =INT($C39*H21) -> 0 | I39: =INT($C39*I21) -> 0 | J39: =INT($C39*J21) -> 0 | K39: =INT($C39*K21) -> 0 | ... O39: =INT($C39*O21) -> 0 | P39: =SUM(D39:O39) -> 0 | Q39: =IF(ISERROR(P39/$P$41),0,P39/$P$41) -> 0
A40: =IF(ISBLANK('Sales Details'!A20)," ",('Sales Details'!A20)) | C40: ='Sales Details'!C20 -> 0 | D40: =INT($C40*D22) -> 0 | E40: =INT($C40*E22) -> 0 | F40: =INT($C40*F22) -> 0 | G40: =INT($C40*G22) -> 0 | H40: =INT($C40*H22) -> 0 | I40: =INT($C40*I22) -> 0 | J40: =INT($C40*J22) -> 0 | K40: =INT($C40*K22) -> 0 | ... O40: =INT($C40*O22) -> 0 | P40: =SUM(D40:O40) -> 0 | Q40: =IF(ISERROR(P40/$P$41),0,P40/$P$41) -> 0
A41: Total sales revenue | D41: =ROUND(SUM(D26:D40),0) -> 0 | E41: =ROUND(SUM(E26:E40),0) -> 0 | F41: =ROUND(SUM(F26:F40),0) -> 0 | G41: =ROUND(SUM(G26:G40),0) -> 0 | H41: =ROUND(SUM(H26:H40),0) -> 0 | I41: =ROUND(SUM(I26:I40),0) -> 0 | J41: =ROUND(SUM(J26:J40),0) -> 0 | K41: =ROUND(SUM(K26:K40),0) -> 0 | ... P41: =ROUND(SUM(P26:P40),0) -> 0 | Q41: =Q26+Q27+Q28+Q29+Q30+Q31+Q32+Q33+Q34+Q35+Q36+Q37+Q38+Q39+Q40 -> 0
A43: Total banked per month | D43: ='Debtors analysis'!C22 -> #VALUE! | E43: ='Debtors analysis'!D22 -> #VALUE! | F43: ='Debtors analysis'!E22 -> #VALUE! | G43: ='Debtors analysis'!F22 -> #VALUE! | H43: ='Debtors analysis'!G22 -> #VALUE! | I43: ='Debtors analysis'!H22 -> #VALUE! | J43: ='Debtors analysis'!I22 -> #VALUE! | K43: ='Debtors analysis'!J22 -> #VALUE! | ... O43: ='Debtors analysis'!N22 -> #VALUE! | P43: =SUM(D43:O43) -> #VALUE!
A45: Cost of Sales Schedule Year 1
B46: COGS | C46: % cost of goods sold | D46: =D6 -> Jan | E46: =E6 -> Feb | F46: =F6 -> Mar | G46: =G6 -> Apr | H46: =H6 -> May | I46: =I6 -> Jun | J46: =J6 -> Jul | K46: =K6 -> Aug | ... O46: =O6 -> Dec | P46: Total
A47: =IF(ISBLANK('Sales Details'!A6),"",('Sales Details'!A6)) -> Test-category-1 | B47: ='Sales Details'!D6 -> 1000 | C47: =IF(ISBLANK('Sales Details'!A6),0,IF('Sales Details'!E6>0.01,(100%-'Sales Details'!E6),0)) -> 0.1 | D47: =IF(ISBLANK(C47)," ",(C47*D26)) -> 0 | E47: =IF(ISBLANK(C47)," ",(C47*E26)) -> 0 | F47: =IF(ISBLANK(C47)," ",(C47*F26)) -> 0 | G47: =IF(ISBLANK(C47)," ",(C47*G26)) -> 0 | H47: =IF(ISBLANK(C47)," ",(C47*H26)) -> 0 | I47: =IF(ISBLANK(C47)," ",(C47*I26)) -> 0 | J47: =IF(ISBLANK(C47)," ",(C47*J26)) -> 0 | K47: =IF(ISBLANK(C47)," ",(C47*K26)) -> 0 | L47: =IF(ISBLANK(C47)," ",(C47*L26)) -> 0 | M47: =IF(ISBLANK(C47)," ",(C47*M26)) -> 0 | N47: =IF(ISBLANK(C47)," ",(C47*N26)) -> 0 | O47: =IF(ISBLANK(C47)," ",(C47*O26)) -> 0 | P47: =SUM(D47:O47) -> 0
...

Sheet Sales Forecast Year 2
A1: Financial plan of | C1: ='Set Up Details'!C2 -> Test1
A3: Sales Forecast Year 2
